Workbook
Name ACTION: #REF!
Name ACTION: #REF!

Sheet Cover
B2: TEST REPORT DOCUMENT
A4: Project Name | B4: <Project Name> | E4: Creator
A5: Project Code | B5: <Project Code> | E5: Issue Date | F5: <Date when this test report is created>
A6: Document Code | B6: =B5&"_"&"XXX"&"_"&"vx.x" -> <Project Code>_XXX_vx.x | E6: Version
A9: Record of change
A10: Effective Date | B10: Version | C10: Change Item | D10: *A,D,M | E10: Change description | F10: Reference
A11: <Date when these changes are effective> | F11: <List of documents which are refered in this version.>

Sheet Test Cases
D1: TEST CASE LIST
B3: Project Name | D3: =#REF! -> #REF!
B4: Project Code | D4: =#REF! -> #REF!
B5: Test Environment Setup Description | D5: <List enviroment requires in this system 1. Server 2. Database 3. Web Browser ... >
B8: No | C8: Function Name | D8: Sheet Name | E8: Description | F8: Pre-Condition
B9: 1 | C9: Sign Up & Role Registration | D9: Sign Up & Role Registration
B10: 2 | C10: Sign In With Password | D10: Sign In
B11: 3 | C11: Forgot & Reset Password Flow | D11: Forgot & Reset Password Flow
B12: 4 | C12: Manage User Profile, Avatar & Settings | D12: Manage User Profile, Avatar & Settings
B13: 5 | C13: Identity Document Verification | D13: Identity Document Verification
B14: 6 | C14: Create Snake Catching Request (Images, GPS, Species) | D14: Create Snake Catching Request (Images, GPS, Species)
B15: 7 | C15: Process Catching Deposit (Round 1) | D15: Process Catching Deposit (Round 1)
B16: 8 | C16: Operator Verification & Assignment | D16: Operator Verification & Assignment
B17: 9 | C17: Rescuer EnRoute & Arrived Tracking | D17: Rescuer EnRoute & Arrived Tracking
B18: 10 | C18: Rescuer Mission Execution & Evidence Upload | D18: Rescuer Mission Execution & Evidence Upload
B19: 11 | C19: Process Actual Service Payment (Round 2) | D19: Process Actual Service Payment (Round 2)
B20: 12 | C20: Cancel Catching Request & Deposit Refund | D20: Cancel Catching Request & Deposit Refund
... B53: 45 | C53: Content: Blogs Database Management | D53: Content: Blogs Database Management

Sheet Test Statistics
B1: TEST STATISTICS
B3: Project Name | C3: <Project Name> | E3: Creator
B4: Project Code | C4: <Project Code> | E4: Reviewer/Approver
B5: Document Code | C5: =C4&"_"&"Test Report"&"_"&"vx.x" -> <Project Code>_Test Report_vx.x | E5: Issue Date | H5: <Date when this test report is created>
B6: Notes | C6: <List modules included in this release> ex: Release 1 includes 2 modules: Module1 and Module2
B10: No | C10: Module code | D10: Passed | E10: Failed | F10: Pending | G10: N/A | H10: Number of test cases
B11: 1 | C11: Sign Up & Role Registration | D11: ='Sign Up & Role Registration'!B6 -> 7 | E11: 0 | F11: 0 | G11: 0 | H11: ='Sign Up & Role Registration'!B4 -> 7
B12: 2 | C12: Sign In | D12: ='Sign In'!B6 -> 9 | E12: 0 | F12: 0 | G12: 0 | H12: ='Sign In'!B4 -> 9
B13: 3 | C13: Forgot & Reset Password Flow | D13: ='Forgot & Reset Password Flow'!B6 -> 5 | E13: 0 | F13: 0 | G13: 0 | H13: ='Forgot & Reset Password Flow'!B4 -> 5
B14: 4 | C14: Manage User Profile, Avatar & Settings | D14: ='Manage User Profile, Avatar & S'!B6 -> 7 | E14: 0 | F14: 0 | G14: 0 | H14: ='Manage User Profile, Avatar & S'!B4 -> 7
B15: 5 | C15: Identity Document Verification | D15: ='Identity Document Verification'!B6 -> 7 | E15: 0 | F15: 0 | G15: 0 | H15: ='Identity Document Verification'!B4 -> 7
B16: 6 | C16: Create Snake Catching Request (Images, GPS, Species) | D16: ='Create Snake Catching Request'!B6 -> 8 | E16: 0 | F16: 0 | G16: 0 | H16: ='Create Snake Catching Request'!B4 -> 8
B17: 7 | C17: Process Catching Deposit (Round 1) | D17: ='Process Catching Deposit (Round'!B6 -> 8 | E17: 0 | F17: 0 | G17: 0 | H17: ='Process Catching Deposit (Round'!B4 -> 8
B18: 8 | C18: Operator Verification & Assignment | D18: ='Operator Verification & Assignm'!B6 -> 6 | E18: 0 | F18: 0 | G18: 0 | H18: ='Operator Verification & Assignm'!B4 -> 6
B19: 9 | C19: Rescuer EnRoute & Arrived Tracking | D19: ='Rescuer EnRoute & Arrived Track'!B6 -> 6 | E19: 0 | F19: 0 | G19: 0 | H19: ='Rescuer EnRoute & Arrived Track'!B4 -> 6
B20: 10 | C20: Rescuer Mission Execution & Evidence Upload | D20: 0 | E20: 0 | F20: 0 | G20: 0 | H20: 0
B21: 11 | C21: Process Actual Service Payment (Round 2) | D21: 0 | E21: 0 | F21: 0 | G21: 0 | H21: 0
B22: 12 | C22: Cancel Catching Request & Deposit Refund | D22: 0 | E22: 0 | F22: 0 | G22: 0 | H22: 0
B23: 13 | C23: Trigger SOS Alarm (GPS, Symptoms, AI check) | D23: 0 | E23: 0 | F23: 0 | G23: 0 | H23: 0
B24: 14 | C24: Operator Fast-Track Verification & Assignment | D24: 0 | E24: 0 | F24: 0 | G24: 0 | H24: 0
B25: 15 | C25: Rescuer On-Scene Navigation & AI Triage | D25: 0 | E25: 0 | F25: 0 | G25: 0 | H25: 0
B26: 16 | C26: SOS Find Nearest Hospital (Navigation) | D26: 0 | E26: 0 | F26: 0 | G26: 0 | H26: 0
B27: 17 | C27: Process SOS Post-Service Payment | D27: 0 | E27: 0 | F27: 0 | G27: 0 | H27: 0
B28: 18 | C28: View & Filter Expert Directory | D28: ='View & Filter Expert Directory'!B6 -> 5 | E28: 0 | F28: 0 | G28: 0 | H28: 5
B29: 19 | C29: Book Instant Consultation | D29: ='Book Instant Consultation'!B6 -> 5 | E29: 0 | F29: 0 | G29: 0 | H29: 5
B30: 20 | C30: Book Scheduled Consultation | D30: ='Book Scheduled Consultation'!B6 -> 5 | E30: 0 | F30: 0 | G30: 0 | H30: 5
B31: 21 | C31: Process Consultation Escrow Payment | D31: ='Process Consultation Escrow Pay'!B6 -> 6 | E31: 0 | F31: 0 | G31: 0 | H31: 6
B32: 22 | C32: WebRTC Video Room & Waiting Room Logic | D32: 5 | E32: 0 | F32: 0 | G32: 0 | H32: 5
B33: 23 | C33: Cancellation & Escrow Refund Handling | D33: ='Cancellation & Escrow Refund Ha'!B6 -> 4 | E33: 0 | F33: 0 | G33: 0 | H33: 4
B34: 24 | C34: Read Community Blog & Safety Alerts | D34: 0 | E34: 0 | F34: 0 | G34: 0 | H34: 0
B35: 25 | C35: Manage Blog Posts (Admin/Operator) | D35: 0 | E35: 0 | F35: 0 | G35: 0 | H35: 0
B36: 26 | C36: Search & View Snake Library (Encyclopedia) | D36: 0 | E36: 0 | F36: 0 | G36: 0 | H36: 0
B37: 27 | C37: Search & View First Aid Protocol Guides | D37: 0 | E37: 0 | F37: 0 | G37: 0 | H37: 0
B38: 28 | C38: Access Rescuer Training Lessons | D38: 0 | E38: 0 | F38: 0 | G38: 0 | H38: 0
B39: 29 | C39: Manage SnakeAidPay Wallet (Top-up, History, Withdraw) | D39: 0 | E39: 0 | F39: 0 | G39: 0 | H39: 0
B40: 30 | C40: External Payment Interface (PayOS Callback) | D40: 0 | E40: 0 | F40: 0 | G40: 0 | H40: 0
B41: 31 | C41: Notification Tab & SignalR Broadcasts | D41: 0 | E41: 0 | F41: 0 | G41: 0 | H41: 0
B42: 32 | C42: Submit Ratings & Read Feedback | D42: 0 | E42: 0 | F42: 0 | G42: 0 | H42: 0
B43: 33 | C43: View Mission & Consultation History (Filtering, Detail) | D43: 0 | E43: 0 | F43: 0 | G43: 0 | H43: 0
B44: 34 | C44: Operator Dashboard & Admin Dashboard | D44: ='Operator Dashboard & Admin Dash'!B6 -> 13 | E44: 0 | F44: 0 | G44: 0 | H44: 13
...

Sheet Sign Up & Role Registration
A2: Feature | B2: Sign Up & Role Registration | R2: Passed
A3: Test requirement | B3: Register using email/password with profile data, accept required terms, complete OTP verification, and continue through role-specific onboarding. | R3: Failed
A4: Number of TCs | B4: =COUNTA(A12:A997) -> 7 | R4: Pending
A5: Testing Round | B5: Passed | C5: Failed | D5: Pending | E5: N/A | R5: N/A
A6: Round 1 | B6: =COUNTIF($F10:$F995,B5) -> 7 | C6: =COUNTIF($F10:$F995,C5) -> 0 | D6: =COUNTIF($F10:$F995,D5) -> 0 | E6: =COUNTIF($F10:$F995,E5) -> 0
A7: Round 2 | B7: =COUNTIF($I10:$I995,B5) -> 7 | C7: =COUNTIF($I10:$I995,C5) -> 0 | D7: =COUNTIF($I10:$I995,D5) -> 0 | E7: =COUNTIF($I10:$I995,E5) -> 0
A8: Round 3 | B8: =COUNTIF($L10:$L995,B5) -> 7 | C8: =COUNTIF($L10:$L995,C5) -> 0 | D8: =COUNTIF($L10:$L995,D5) -> 0 | E8: =COUNTIF($L10:$L991,E5) -> 0
A10: Test Case ID | B10: Test Case Description | C10: Test Case Procedure | D10: Expected Results | E10: Pre-conditions | F10: Round 1 | G10: Test date | H10: Tester | I10: Round 2 | J10: Test date | K10: Tester | L10: Round 3 | M10: Test date | N10: Tester | O10: Note
A11: Sign Up & Role Registration
A12: TC101 | B12: Successful Member sign-up with valid required data | C12: 1. Open the app and select the Member role card "Người Dùng". 2. On the login screen, click "Đăng ký ngay". 3. Enter valid values for all required fields. 4. Click "Đăng Ký". | D12: The system shows "Đăng ký thành công! Mã OTP đã được gửi đến email của bạn" and navigates to OTP verification. | E12: Authentication backend is available; email is not registered. | F12: Passed | H12: KhoaPA | I12: Passed | K12: TrungDN | L12: Passed | N12: DuongNM
A13: TC102 | B13: Expert registration follows approval workflow correctly | C13: 1. Open the app and select the Expert role card "Chuyên Gia". 2. On the login screen, click "Đăng ký ngay" and complete required fields. 3. Click "Tiếp Tục" to submit registration. 4. On "Xác Thực OTP" screen, enter a valid 6-digit code. 5. Continue to the pending approval flow and document submission step "Nộp Chứng Chỉ" according to the configured Expert onboarding route. | D13: Expert account is not considered fully verified until OTP succeeds; after successful OTP, user proceeds to pending/document onboarding flow. | E13: Expert approval workflow is enabled; email is not registered; OTP delivery is available. | F13: Passed | H13: KhoaPA | I13: Passed | K13: TrungDN | L13: Passed | N13: DuongNM
A14: TC103 | B14: OTP verification succeeds with a valid 6-digit code | C14: 1. Complete a new registration flow until the "Xác Thực OTP" screen appears. 2. Enter a valid 6-digit OTP. 3. Click "Xác Nhận". | D14: Verification succeeds and user moves to the next step. | E14: A newly registered account exists; valid OTP has been sent to email. | F14: Passed | H14: KhoaPA | I14: Passed | K14: TrungDN | L14: Passed | N14: DuongNM
A15: TC104 | B15: OTP verification is blocked for invalid or incomplete code | C15: 1. Open "Xác Thực OTP" screen. 2. Enter fewer than 6 digits or an invalid code. 3. Click "Xác Nhận". | D15: App shows validation or verification error (for example "Vui lòng nhập đủ 6 số") and stays on OTP screen. | E15: OTP screen is reachable from registration flow. | F15: Passed | H15: KhoaPA | I15: Passed | K15: TrungDN | L15: Passed | N15: DuongNM
A16: TC105 | B16: Required-field validation blocks incomplete sign-up | C16: 1. Open the Member registration screen or the Expert registration screen. 2. Leave at least one required field empty (for example, Email). 3. Submit with the role-specific primary action: Member clicks "Đăng Ký", Expert clicks "Tiếp Tục". | D16: Form submission is blocked and validation errors are displayed at missing fields. | E16: Registration screen is loaded successfully. | F16: Passed | H16: KhoaPA | I16: Passed | K16: TrungDN | L16: Passed | N16: DuongNM
A17: TC106 | B17: Weak password validation is enforced | C17: 1. Open the Member registration screen or the Expert registration screen. 2. Enter a weak password (too short or missing uppercase/digit). 3. Submit with the role-specific primary action: Member clicks "Đăng Ký", Expert clicks "Tiếp Tục". | D17: Validation error is shown (for example "Mật khẩu phải có ít nhất 1 chữ viết hoa" / "Mật khẩu phải có ít nhất 1 chữ số"); account is not created. | E17: Password policy is active. | F17: Passed | H17: KhoaPA | I17: Passed | K17: TrungDN | L17: Passed | N17: DuongNM
A18: TC107 | B18: Confirm-password mismatch is rejected | C18: 1. Open the Member registration screen or the Expert registration screen. 2. Enter different values for password and confirm password. 3. Submit with the role-specific primary action: Member clicks "Đăng Ký", Expert clicks "Tiếp Tục". | D18: The error "Mật khẩu không khớp" is shown and registration request is not sent. | E18: Registration screen is functioning normally. | F18: Passed | H18: KhoaPA | I18: Passed | K18: TrungDN | L18: Passed | N18: DuongNM

Sheet Sign In
A2: Feature | B2: Sign In | R2: Passed
A3: Test requirement | B3: Sign in using email/password for all roles, enforce required-field validation and role matching, and support remember-login behavior. | R3: Failed
A4: Number of TCs | B4: =COUNTA(A12:A995) -> 9 | R4: Pending
A5: Testing Round | B5: Passed | C5: Failed | D5: Pending | E5: N/A | R5: N/A
A6: Round 1 | B6: =COUNTIF($F10:$F993,B5) -> 9 | C6: =COUNTIF($F10:$F993,C5) -> 0 | D6: =COUNTIF($F10:$F993,D5) -> 0 | E6: =COUNTIF($F10:$F993,E5) -> 0
A7: Round 2 | B7: =COUNTIF($I10:$I993,B5) -> 9 | C7: =COUNTIF($I10:$I993,C5) -> 0 | D7: =COUNTIF($I10:$I993,D5) -> 0 | E7: =COUNTIF($I10:$I993,E5) -> 0
A8: Round 3 | B8: =COUNTIF($L10:$L993,B5) -> 9 | C8: =COUNTIF($L10:$L993,C5) -> 0 | D8: =COUNTIF($L10:$L993,D5) -> 0 | E8: =COUNTIF($L10:$L991,E5) -> 0
A10: Test Case ID | B10: Test Case Description | C10: Test Case Procedure | D10: Expected Results | E10: Pre-conditions | F10: Round 1 | G10: Test date | H10: Tester | I10: Round 2 | J10: Test date | K10: Tester | L10: Round 3 | M10: Test date | N10: Tester | O10: Note
A11: Sign In
A12: TC201 | B12: Member signs in successfully with valid credentials | C12: 1. Open the app and select Member role "Người Dùng". 2. Enter valid Email and Password. 3. Click "Đăng Nhập". | D12: The system shows "Đăng nhập thành công! Chào mừng [Tên]" and navigates to Member home screen. | E12: Member account exists and is active. | F12: Passed | H12: KhoaPA | I12: Passed | K12: TrungDN | L12: Passed | N12: DuongNM
A13: TC202 | B13: Expert signs in successfully with valid credentials | C13: 1. Open the app and select Expert role "Chuyên Gia". 2. Enter valid Email and Password. 3. Click "Đăng Nhập". | D13: Login succeeds and user is navigated to Expert home screen. | E13: Expert account is approved and active. | F13: Passed | H13: KhoaPA | I13: Passed | K13: TrungDN | L13: Passed | N13: DuongNM
A14: TC203 | B14: Rescuer signs in successfully with valid credentials | C14: 1. Open the app and select Rescuer role "Người Cứu Hộ". 2. Enter valid Email and Password. 3. Click "Đăng Nhập". | D14: Login succeeds and user is navigated to Rescuer home screen. | E14: Rescuer account exists and is active. | F14: Passed | H14: KhoaPA | I14: Passed | K14: TrungDN | L14: Passed | N14: DuongNM
A15: TC204 | B15: Role mismatch is blocked at login | C15: 1. Open Expert login screen. 2. Try to sign in with a Member account. 3. Click "Đăng Nhập". | D15: The system shows "Tài khoản này không phải là Expert. Vui lòng chọn đúng role khi đăng nhập." and blocks access. | E15: A valid Member account is available. | F15: Passed | H15: KhoaPA | I15: Passed | K15: TrungDN | L15: Passed | N15: DuongNM
A16: TC205 | B16: Required-field validation on login is enforced | C16: 1. Open any role login screen. 2. Leave Email or Password empty. 3. Click "Đăng Nhập". | D16: Validation errors are shown and login request is not sent. | E16: Login screen loads successfully. | F16: Passed | H16: KhoaPA | I16: Passed | K16: TrungDN | L16: Passed | N16: DuongNM
A17: TC206 | B17: Admin logs in successfully with valid credentials | C17: 1. Open web login page. 2. Select role Admin. 3. Enter valid Admin email and password. 4. Click "Đăng nhập". | D17: Login succeeds and user is redirected to Admin home/dashboard page. | E17: Active Admin account exists. | F17: Passed | H17: KhoaPA | I17: Passed | K17: DuongNM | L17: Passed | N17: KhoaPA
A18: TC207 | B18: Operator logs in successfully with valid credentials | C18: 1. Open web login page. 2. Select role Operator. 3. Enter valid Operator email and password. 4. Click "Đăng nhập". | D18: Login succeeds and user is redirected to Operator home/dashboard page. | E18: Active Operator account exists. | F18: Passed | H18: KhoaPA | I18: Passed | K18: DuongNM | L18: Passed | N18: KhoaPA
A19: TC208 | B19: Role mismatch is blocked at login | C19: 1. Open web login page. 2. Select role Admin. 3. Enter credentials of an Operator account. 4. Click "Đăng nhập". | D19: Login is blocked and message about wrong role is shown; user is not redirected to Admin pages. | E19: Valid Operator account exists. | F19: Passed | H19: KhoaPA | I19: Passed | K19: DuongNM | L19: Passed | N19: KhoaPA
A20: TC209 | B20: Required-field validation is shown when email/password are empty | C20: 1. Open web login page. 2. Select role Admin or Operator. 3. Leave Email and Password empty. 4. Click "Đăng nhập". | D20: Validation message requiring input is shown and login request is not sent. | E20: Login page loads successfully. | F20: Passed | H20: KhoaPA | I20: Passed | K20: DuongNM | L20: Passed | N20: KhoaPA

Sheet Forgot & Reset Password Flow
A2: Feature | B2: Forgot & Reset Password Flow | R2: Passed
A3: Test requirement | R3: Failed
A4: Number of TCs | B4: =COUNTA(A12:A995) -> 5 | R4: Pending
A5: Testing Round | B5: Passed | C5: Failed | D5: Pending | E5: N/A | R5: N/A
A6: Round 1 | B6: =COUNTIF($F10:$F993,B5) -> 5 | C6: =COUNTIF($F10:$F993,C5) -> 0 | D6: =COUNTIF($F10:$F993,D5) -> 0 | E6: =COUNTIF($F10:$F993,E5) -> 0
A7: Round 2 | B7: =COUNTIF($I10:$I993,B5) -> 5 | C7: =COUNTIF($I10:$I993,C5) -> 0 | D7: =COUNTIF($I10:$I993,D5) -> 0 | E7: =COUNTIF($I10:$I993,E5) -> 0
A8: Round 3 | B8: =COUNTIF($L10:$L993,B5) -> 5 | C8: =COUNTIF($L10:$L993,C5) -> 0 | D8: =COUNTIF($L10:$L993,D5) -> 0 | E8: =COUNTIF($L10:$L991,E5) -> 0
A10: Test Case ID | B10: Test Case Description | C10: Test Case Procedure | D10: Expected Results | E10: Pre-conditions | F10: Round 1 | G10: Test date | H10: Tester | I10: Round 2 | J10: Test date | K10: Tester | L10: Round 3 | M10: Test date | N10: Tester | O10: Note
A11: Forgot & Reset Password Flow
A12: TC301 | F12: Passed | H12: KhoaPA | I12: Passed | K12: TrungDN | L12: Passed | N12: DuongNM
A13: TC302 | F13: Passed | H13: KhoaPA | I13: Passed | K13: TrungDN | L13: Passed | N13: DuongNM
A14: TC303 | F14: Passed | H14: KhoaPA | I14: Passed | K14: TrungDN | L14: Passed | N14: DuongNM
A15: TC304 | F15: Passed | H15: KhoaPA | I15: Passed | K15: TrungDN | L15: Passed | N15: DuongNM
A16: TC305 | F16: Passed | H16: KhoaPA | I16: Passed | K16: TrungDN | L16: Passed | N16: DuongNM

Sheet Manage User Profile, Avatar & S
A2: Feature | B2: Manage User Profile, Avatar & Settings | R2: Passed
A3: Test requirement | B3: Allow authenticated users to view and update profile/avatar, access settings, manage privacy options, view wallet balance, and log out securely. | R3: Failed
A4: Number of TCs | B4: =COUNTA(A12:A993) -> 7 | R4: Pending
A5: Testing Round | B5: Passed | C5: Failed | D5: Pending | E5: N/A | R5: N/A
A6: Round 1 | B6: =COUNTIF($F10:$F991,B5) -> 7 | C6: =COUNTIF($F10:$F991,C5) -> 0 | D6: =COUNTIF($F10:$F991,D5) -> 0 | E6: =COUNTIF($F10:$F991,E5) -> 0
A7: Round 2 | B7: =COUNTIF($I10:$I991,B5) -> 7 | C7: =COUNTIF($I10:$I991,C5) -> 0 | D7: =COUNTIF($I10:$I991,D5) -> 0 | E7: =COUNTIF($I10:$I991,E5) -> 0
A8: Round 3 | B8: =COUNTIF($L10:$L991,B5) -> 7 | C8: =COUNTIF($L10:$L991,C5) -> 0 | D8: =COUNTIF($L10:$L991,D5) -> 0 | E8: =COUNTIF($L10:$L991,E5) -> 0
A10: Test Case ID | B10: Test Case Description | C10: Test Case Procedure | D10: Expected Results | E10: Pre-conditions | F10: Round 1 | G10: Test date | H10: Tester | I10: Round 2 | J10: Test date | K10: Tester | L10: Round 3 | M10: Test date | N10: Tester | O10: Note
A11: Manage User Profile, Avatar & Settings
A12: TC401 | B12: User profile is displayed correctly | C12: 1. Sign in as Member. 2. Open profile screen. | D12: Profile shows avatar, full name rating, and reputation data correctly. | E12: User account has profile data. | F12: Passed | H12: KhoaPA | I12: Passed | K12: TrungDN | L12: Passed | N12: DuongNM
A13: TC402 | B13: User can open Edit Profile from profile screen | C13: 1. On profile screen, click "Chỉnh Sửa Hồ Sơ". | D13: User is navigated to Edit Profile screen successfully. | E13: User is signed in. | F13: Passed | H13: KhoaPA | I13: Passed | K13: TrungDN | L13: Passed | N13: DuongNM
A14: TC403 | B14: User avatar upload and save works | C14: 1. Open Edit Profile screen. 2. Tap camera icon to choose a new avatar image. 3. Click "Lưu Thay Đổi". | D14: New avatar is displayed and success message "Lưu thành công" appears. | E14: Device photo permission is granted; avatar upload API is available. | F14: Passed | H14: KhoaPA | I14: Passed | K14: TrungDN | L14: Passed | N14: DuongNM
A15: TC404 | B15: User profile information can be updated | C15: 1. Open Edit Profile screen. 2. Update valid profile data (for example name or phone). 3. Click "Lưu Thay Đổi". | D15: Updated data is saved and reflected when returning to profile screen. | E15: Profile update API is available. | F15: Passed | H15: KhoaPA | I15: Passed | K15: TrungDN | L15: Passed | N15: DuongNM
A16: TC405 | B16: User settings screen displays account options | C16: 1. From profile screen, open settings using "Cài Đặt". 2. Verify account options area. | D16: Account options are displayed correctly, including edit profile and change password entries. | E16: User is signed in. | F16: Passed | H16: KhoaPA | I16: Passed | K16: TrungDN | L16: Passed | N16: DuongNM
A17: TC406 | B17: Wallet balance is shown and refreshable in profile screen | C17: 1. On profile screen. 2. Scroll down to see the wallet balance displayed. | D17: Wallet balance is shown in correct currency format; error state is shown appropriately on network/API failure. | E17: Wallet API is available (or test data is configured). | F17: Passed | H17: KhoaPA | I17: Passed | K17: TrungDN | L17: Passed | N17: DuongNM
A18: TC407 | B18: User can log out from settings | C18: 1. Open settings screen "Cài Đặt". 2. Click "Đăng xuất" and confirm. | D18: Session is cleared and user returns to role-selection/login flow. | E18: User is currently signed in. | F18: Passed | H18: KhoaPA | I18: Passed | K18: TrungDN | L18: Passed | N18: DuongNM

Sheet Identity Document Verification
A2: Feature | B2: Identity Document Verification | R2: Passed
A3: Test requirement | R3: Failed
A4: Number of TCs | B4: =COUNTA(A12:A993) -> 7 | R4: Pending
A5: Testing Round | B5: Passed | C5: Failed | D5: Pending | E5: N/A | R5: N/A
A6: Round 1 | B6: =COUNTIF($F10:$F991,B5) -> 7 | C6: =COUNTIF($F10:$F991,C5) -> 0 | D6: =COUNTIF($F10:$F991,D5) -> 0 | E6: =COUNTIF($F10:$F991,E5) -> 0
A7: Round 2 | B7: =COUNTIF($I10:$I991,B5) -> 7 | C7: =COUNTIF($I10:$I991,C5) -> 0 | D7: =COUNTIF($I10:$I991,D5) -> 0 | E7: =COUNTIF($I10:$I991,E5) -> 0
A8: Round 3 | B8: =COUNTIF($L10:$L991,B5) -> 7 | C8: =COUNTIF($L10:$L991,C5) -> 0 | D8: =COUNTIF($L10:$L991,D5) -> 0 | E8: =COUNTIF($L10:$L991,E5) -> 0
A10: Test Case ID | B10: Test Case Description | C10: Test Case Procedure | D10: Expected Results | E10: Pre-conditions | F10: Round 1 | G10: Test date | H10: Tester | I10: Round 2 | J10: Test date | K10: Tester | L10: Round 3 | M10: Test date | N10: Tester | O10: Note
A11: Identity Document Verification
A12: TC501 | F12: Passed | H12: KhoaPA | I12: Passed | K12: TrungDN | L12: Passed | N12: DuongNM
A13: TC501 | F13: Passed | H13: KhoaPA | I13: Passed | K13: TrungDN | L13: Passed | N13: DuongNM
A14: TC501 | F14: Passed | H14: KhoaPA | I14: Passed | K14: TrungDN | L14: Passed | N14: DuongNM
A15: TC501 | F15: Passed | H15: KhoaPA | I15: Passed | K15: TrungDN | L15: Passed | N15: DuongNM
A16: TC501 | F16: Passed | H16: KhoaPA | I16: Passed | K16: TrungDN | L16: Passed | N16: DuongNM
A17: TC501 | F17: Passed | H17: KhoaPA | I17: Passed | K17: TrungDN | L17: Passed | N17: DuongNM
A18: TC501 | F18: Passed | H18: KhoaPA | I18: Passed | K18: TrungDN | L18: Passed | N18: DuongNM

Sheet Create Snake Catching Request
A2: Feature | B2: Create Snake Catching Request (Images, GPS, Species) | R2: Passed
A3: Test requirement | B3: Create request from "Báo Cáo Phát Hiện Rắn" with required location + address detail; support both flows "Chụp Ảnh" and "Chọn Loài Rắn" | R3: Failed
A4: Number of TCs | B4: =COUNTA(A12:A993) -> 8 | R4: Pending
A5: Testing Round | B5: Passed | C5: Failed | D5: Pending | E5: N/A | R5: N/A
A6: Round 1 | B6: =COUNTIF($F10:$F991,B5) -> 8 | C6: =COUNTIF($F10:$F991,C5) -> 0 | D6: =COUNTIF($F10:$F991,D5) -> 0 | E6: =COUNTIF($F10:$F991,E5) -> 0
A7: Round 2 | B7: =COUNTIF($I10:$I991,B5) -> 8 | C7: =COUNTIF($I10:$I991,C5) -> 0 | D7: =COUNTIF($I10:$I991,D5) -> 0 | E7: =COUNTIF($I10:$I991,E5) -> 0
A8: Round 3 | B8: =COUNTIF($L10:$L991,B5) -> 8 | C8: =COUNTIF($L10:$L991,C5) -> 0 | D8: =COUNTIF($L10:$L991,D5) -> 0 | E8: =COUNTIF($L10:$L991,E5) -> 0
A10: Test Case ID | B10: Test Case Description | C10: Test Case Procedure | D10: Expected Results | E10: Pre-conditions | F10: Round 1 | G10: Test date | H10: Tester | I10: Round 2 | J10: Test date | K10: Tester | L10: Round 3 | M10: Test date | N10: Tester | O10: Note
A11: Create Snake Catching Request (Images, GPS, Species)
A12: TC601 | B12: Create request successfully via photo flow (single) | C12: 1) Open Home as Member 2) Open "Báo Cáo Phát Hiện Rắn" 3) Select "1 loài rắn" and click "Tiếp tục" 4) Keep tab "Chụp Ảnh" 5) Add slot-1 image via "Chụp ảnh" or "Album ảnh" 6) Click "Chọn vị trí" and select address or "Lấy vị trí hiện tại" 7) Fill "GHI CHÚ ĐỊA CHỈ CHI TIẾT *" 8) Click "Gửi Báo Cáo" | D12: Request is created and app navigates to success screen with "Yêu Cầu Đã Được Gửi!" | E12: Member logged in; internet available; create-request API available | F12: Passed | H12: TrungDN | I12: Passed | K12: TrungDN | L12: Passed | N12: DuongNM
A13: TC602 | B13: Create request successfully via manual species flow | C13: 1) Open report flow and select "1 loài rắn" -> "Tiếp tục" 2) Switch to tab "Chọn Loài Rắn" 3) Select one species 4) Set location via "Chọn vị trí" dialog 5) Fill "GHI CHÚ ĐỊA CHỈ CHI TIẾT *" 6) Click "Gửi Báo Cáo" | D13: Request is submitted successfully and success screen is shown | E13: Member logged in; species API available | F13: Passed | H13: TrungDN | I13: Passed | K13: TrungDN | L13: Passed | N13: DuongNM
A14: TC603 | B14: Block continue when quantity not selected | C14: 1) Open "Báo Cáo Phát Hiện Rắn" 2) Do not select "1 loài rắn"/"2-5 loài rắn"/"Ổ rắn" 3) Observe "Tiếp tục" | D14: "Tiếp tục" is disabled; cannot go to detail screen | E14: Member is on quantity selection screen | F14: Passed | H14: TrungDN | I14: Passed | K14: TrungDN | L14: Passed | N14: DuongNM
A15: TC604 | B15: Block submit when location is missing | C15: 1) Prepare valid photo/species data in detail screen 2) Fill "GHI CHÚ ĐỊA CHỈ CHI TIẾT *" 3) Keep location unset 4) Trigger submit path | D15: Submission is blocked and snackbar "Vui lòng chọn vị trí trước khi gửi" is shown | E15: Member is on report detail screen | F15: Passed | H15: TrungDN | I15: Passed | K15: TrungDN | L15: Passed | N15: DuongNM
A16: TC605 | B16: Require address detail before submit | C16: 1) In detail screen, set valid location + valid photo/species data 2) Leave "GHI CHÚ ĐỊA CHỈ CHI TIẾT *" empty 3) Observe "Gửi Báo Cáo" | D16: "Gửi Báo Cáo" remains disabled until address detail is entered | E16: Member is on report detail screen | F16: Passed | H16: TrungDN | I16: Passed | K16: TrungDN | L16: Passed | N16: DuongNM
A17: TC606 | B17: No AI detection -> switch to manual species | C17: 1) In tab "Chụp Ảnh", upload image with no AI detection 2) Click "Gửi Báo Cáo" 3) In dialog "Không nhận diện được rắn", click "Chọn loài rắn thủ công" | D17: Dialog closes and app switches to tab "Chọn Loài Rắn" | E17: At least one photo uploaded; AI returns no detection | F17: Passed | H17: TrungDN | I17: Passed | K17: TrungDN | L17: Passed | N17: DuongNM
A18: TC607 | B18: No AI detection -> still continue submit | C18: 1) In tab "Chụp Ảnh", upload image with no AI detection 2) Click "Gửi Báo Cáo" 3) In dialog "Không nhận diện được rắn", click "Tiếp tục gửi" | D18: System still creates request and navigates to success screen | E18: Required fields valid; AI returns no detection | F18: Passed | H18: TrungDN | I18: Passed | K18: TrungDN | L18: Passed | N18: DuongNM
A19: TC608 | B19: Validate species selection in manual tab | C19: 1) Switch to "Chọn Loài Rắn" 2) Set location + fill "GHI CHÚ ĐỊA CHỈ CHI TIẾT *" 3) Do not pick any species 4) Click "Gửi Báo Cáo" | D19: Validation error is shown ("Vui lòng chọn loài rắn" or "Vui lòng chọn ít nhất 1 loài rắn") and request is not submitted | E19: Member is on manual species tab | F19: Passed | H19: TrungDN | I19: Passed | K19: TrungDN | L19: Passed | N19: DuongNM

Sheet Process Catching Deposit (Round
A2: Feature | B2: Process Catching Deposit (Round 1) | R2: Passed
A3: Test requirement | B3: Member can open the deposit payment sheet from snake catching request detail, pay using either SnakeAidPay wallet or PayOS, and the deposit becomes confirmed for the request | R3: Failed
A4: Number of TCs | B4: =COUNTA(A12:A993) -> 8 | R4: Pending
A5: Testing Round | B5: Passed | C5: Failed | D5: Pending | E5: N/A | R5: N/A
A6: Round 1 | B6: =COUNTIF($F10:$F991,B5) -> 8 | C6: =COUNTIF($F10:$F991,C5) -> 0 | D6: =COUNTIF($F10:$F991,D5) -> 0 | E6: =COUNTIF($F10:$F991,E5) -> 0
A7: Round 2 | B7: =COUNTIF($I10:$I991,B5) -> 8 | C7: =COUNTIF($I10:$I991,C5) -> 0 | D7: =COUNTIF($I10:$I991,D5) -> 0 | E7: =COUNTIF($I10:$I991,E5) -> 0
A8: Round 3 | B8: =COUNTIF($L10:$L991,B5) -> 8 | C8: =COUNTIF($L10:$L991,C5) -> 0 | D8: =COUNTIF($L10:$L991,D5) -> 0 | E8: =COUNTIF($L10:$L991,E5) -> 0
A10: Test Case ID | B10: Test Case Description | C10: Test Case Procedure | D10: Expected Results | E10: Pre-conditions | F10: Round 1 | G10: Test date | H10: Tester | I10: Round 2 | J10: Test date | K10: Tester | L10: Round 3 | M10: Test date | N10: Tester | O10: Note
A11: Process Catching Deposit (Round 1)
A12: TC701 | B12: Open deposit payment sheet from request detail | C12: 1) Open Home as Member 2) Open "Hoạt Động" 3) Select 1 booking that needs travel fee payment 4) Click button "Thanh toán phí di chuyển" | D12: Payment sheet opens with title "Thanh toán đặt cọc", subtitle "Chọn phương thức thanh toán", and amount row "Đợt 1 — Đặt cọc" | E12: A snake catching booking exists in Activity and still requires round-1 deposit payment | F12: Passed | H12: TrungDN | I12: Passed | K12: TrungDN | L12: Passed | N12: DuongNM
A13: TC702 | B13: Pay deposit successfully using SnakeAidPay wallet | C13: 1) Open the payment sheet 2) In the card "Ví SnakeAidPay", verify sufficient balance is available 3) Tap "Thanh toán bằng ví" | D13: Deposit payment succeeds and success dialog appears with title "Thanh Toán Thành Công!" and subtitle "Đặt cọc phí di chuyển đã được xác nhận." | E13: Member has enough wallet balance; deposit payment sheet is open | F13: Passed | H13: TrungDN | I13: Passed | K13: TrungDN | L13: Passed | N13: DuongNM
A14: TC703 | B14: Wallet payment is blocked when balance is not enough | C14: 1) Open "Báo Cáo Phát Hiện Rắn" 2) Do not select "1 loài rắn"/"2-5 loài rắn"/"Ổ rắn" 3) Observe "Tiếp tục" | D14: "Tiếp tục" is disabled; cannot go to detail screen | E14: Member is on quantity selection screen | F14: Passed | H14: TrungDN | I14: Passed | K14: TrungDN | L14: Passed | N14: DuongNM
A15: TC704 | B15: Pay deposit through PayOS checkout successfully | C15: 1) Open the payment sheet 2) In the card "PayOS", tap "Thanh toán qua PayOS" 3) Complete payment on the PayOS checkout page 4) Return to the app via deep link or app resume | D15: PayOS checkout opens, payment is confirmed, and the request is updated to deposit-paid state | E15: PayOS service is available; request has a valid deposit amount | F15: Passed | H15: TrungDN | I15: Passed | K15: TrungDN | L15: Passed | N15: DuongNM
A16: TC705 | B16: PayOS payment updates request state after return | C16: 1) Start a deposit payment through PayOS 2) Finish the payment successfully 3) Wait for the app to verify the deep link return | D16: The app recognizes the returned payment, clears the pending PayOS context, and the booking shows the deposit as confirmed | E16: A PayOS payment link was created for the current request | F16: Passed | H16: TrungDN | I16: Passed | K16: TrungDN | L16: Passed | N16: DuongNM
A17: TC706 | B17: Cancel PayOS checkout and keep deposit unpaid | C17: 1) Open the payment sheet 2) Tap "Thanh toán qua PayOS" 3) Cancel or close the checkout page before payment is confirmed 4) Return to the request detail screen | D17: Deposit remains unpaid and the request stays in the waiting-for-deposit state | E17: PayOS checkout can be opened from the current request | F17: Passed | H17: TrungDN | I17: Passed | K17: TrungDN | L17: Passed | N17: DuongNM
A18: TC707 | B18: Deposit payment is not allowed when no amount is available | C18: 1) Open a request detail screen that has no valid amount for round-1 payment 2) Open the deposit action if visible or trigger the payment action | D18: App shows the snackbar "Không có thông tin giá để thanh toán" and does not open checkout | E18: Request data is missing deposit amount or estimated price | F18: Passed | H18: TrungDN | I18: Passed | K18: TrungDN | L18: Passed | N18: DuongNM
A19: TC708 | B19: Deposit confirmation enables next rescue flow state | C19: 1) Complete a round-1 payment by wallet or PayOS 2) Reopen the request detail screen 3) Verify the payment state area | D19: The request reflects that round-1 deposit is confirmed and the payment entry changes to "Đã Thanh Toán Phí Di Chuyển" | E19: Deposit payment has been confirmed by the backend | F19: Passed | H19: TrungDN | I19: Passed | K19: TrungDN | L19: Passed | N19: DuongNM

Sheet Operator Verification & Assignm
A2: Feature | B2: Operator Verification & Assignment | R2: Passed
A3: Test requirement | B3: Verify operator can process snake-catching requests on dashboard with correct status transitions, dispatch constraints, and UI feedback | R3: Failed
A4: Number of TCs | B4: =COUNTA(A12:A991) -> 6 | R4: Pending
A5: Testing Round | B5: Passed | C5: Failed | D5: Pending | E5: N/A | R5: N/A
A6: Round 1 | B6: =COUNTIF($F10:$F989,B5) -> 6 | C6: =COUNTIF($F10:$F989,C5) -> 0 | D6: =COUNTIF($F10:$F989,D5) -> 0 | E6: =COUNTIF($F10:$F989,E5) -> 0
A7: Round 2 | B7: =COUNTIF($I10:$I989,B5) -> 6 | C7: =COUNTIF($I10:$I989,C5) -> 0 | D7: =COUNTIF($I10:$I989,D5) -> 0 | E7: =COUNTIF($I10:$I989,E5) -> 0
A8: Round 3 | B8: =COUNTIF($L10:$L989,B5) -> 6 | C8: =COUNTIF($L10:$L989,C5) -> 0 | D8: =COUNTIF($L10:$L989,D5) -> 0 | E8: =COUNTIF($L10:$L989,E5) -> 0
A10: Test Case ID | B10: Test Case Description | C10: Test Case Procedure | D10: Expected Results | E10: Pre-conditions | F10: Round 1 | G10: Test date | H10: Tester | I10: Round 2 | J10: Test date | K10: Tester | L10: Round 3 | M10: Test date | N10: Tester | O10: Note
A11: Operator Verification & Assignment
A12: TC801 | B12: Confirm snake-catching request successfully (Pending -> Confirmed) | C12: 1) Login with Operator account 2) Open Operator Dashboard 3) In tab "Bắt rắn", select a request with status "Chờ xác minh" 4) Open request detail modal 5) Click "Xác nhận yêu cầu" | D12: Request is confirmed; status badge in detail becomes "Đã xác nhận"; success toast "Yêu cầu đã được xác nhận." is shown | E12: Operator account exists; at least one active request in Pending state | F12: Passed | H12: TrungDN | I12: Passed | K12: KhoaPA | L12: Passed | N12: TrungDN
A13: TC802 | B13: Assign rescuer successfully (Confirmed -> Assigned) | C13: 1) Open a request already in status "Đã xác nhận" 2) Click "Điều phối rescuer" 3) In dispatch modal, select one available rescuer 4) Click "Xác nhận điều phối" | D13: Dispatch completes; success toast "Điều phối đội cứu hộ thành công." is shown; request detail displays assigned rescuer id in "Rescuer được phân công" | E13: Request is Confirmed; at least one rescuer is online and available | F13: Passed | H13: TrungDN | I13: Passed | K13: KhoaPA | L13: Passed | N13: TrungDN
A14: TC803 | B14: Cannot dispatch when no rescuer is selected | C14: 1) Open request detail in Confirmed state 2) Click "Điều phối rescuer" 3) Do not select any rescuer in list 4) Observe action button | D14: Button "Xác nhận điều phối" remains disabled until a rescuer is selected | E14: Request is Confirmed; dispatch modal can be opened | F14: Passed | H14: TrungDN | I14: Passed | K14: KhoaPA | L14: Passed | N14: DuongNM
A15: TC804 | B15: Show empty-state when no eligible rescuer exists | C15: 1) Open dispatch modal for a Confirmed request 2) Keep filters "Chỉ trong ca" and "Chỉ online" enabled 3) Ensure no rescuer satisfies current filters | D15: Empty-state message "Không có đội cứu hộ phù hợp bộ lọc." is shown; no dispatch success toast appears | E15: Request is Confirmed; test data has no matching rescuer by shift/online filters | F15: Passed | H15: TrungDN | I15: Passed | K15: KhoaPA | L15: Passed | N15: DuongNM
A16: TC805 | B16: Cancel request from Confirmed state | C16: 1) Open detail of a request in Confirmed state 2) Click "Hủy yêu cầu" 3) Wait for dashboard refresh | D16: Success toast "Yêu cầu đã được hủy." is shown; request is removed from active request list | E16: Request is Confirmed and cancellable by operator | F16: Passed | H16: TrungDN | I16: Passed | K16: KhoaPA | L16: Passed | N16: DuongNM
A17: TC806 | B17: Cancel request from Assigned state | C17: 1) Open detail of a request already assigned 2) Click "Hủy yêu cầu" 3) Confirm dashboard list after action | D17: Success toast "Yêu cầu đã được hủy." is shown; active list no longer contains cancelled request | E17: Request is Assigned and appears in active request list | F17: Passed | H17: TrungDN | I17: Passed | K17: KhoaPA | L17: Passed | N17: DuongNM

Sheet Rescuer EnRoute & Arrived Track
A2: Feature | B2: Rescuer EnRoute & Arrived Tracking | R2: Passed
A3: Test requirement | B3: Rescuer receives assigned mission, starts moving (EnRoute), updates arrival (Arrived), and the app reflects tracking state correctly | R3: Failed
A4: Number of TCs | B4: =COUNTA(A12:A991) -> 6 | R4: Pending
A5: Testing Round | B5: Passed | C5: Failed | D5: Pending | E5: N/A | R5: N/A
A6: Round 1 | B6: =COUNTIF($F10:$F989,B5) -> 6 | C6: =COUNTIF($F10:$F989,C5) -> 0 | D6: =COUNTIF($F10:$F989,D5) -> 0 | E6: =COUNTIF($F10:$F989,E5) -> 0
A7: Round 2 | B7: =COUNTIF($I10:$I989,B5) -> 6 | C7: =COUNTIF($I10:$I989,C5) -> 0 | D7: =COUNTIF($I10:$I989,D5) -> 0 | E7: =COUNTIF($I10:$I989,E5) -> 0
A8: Round 3 | B8: =COUNTIF($L10:$L989,B5) -> 6 | C8: =COUNTIF($L10:$L989,C5) -> 0 | D8: =COUNTIF($L10:$L989,D5) -> 0 | E8: =COUNTIF($L10:$L989,E5) -> 0
A10: Test Case ID | B10: Test Case Description | C10: Test Case Procedure | D10: Expected Results | E10: Pre-conditions | F10: Round 1 | G10: Test date | H10: Tester | I10: Round 2 | J10: Test date | K10: Tester | L10: Round 3 | M10: Test date | N10: Tester | O10: Note
A11: Rescuer EnRoute & Arrived Tracking
A12: TC901 | B12: Open assigned mission and verify start-move action | C12: 1) Login as Rescuer 2) Open "Hoạt Động" tab 3) Click "Xem Chi Tiết" 3) Verify payment check section and primary action area | D12: Primary action "BẮT ĐẦU DI CHUYỂN" is visible; when deposit is not confirmed, button remains disabled and payment hint is shown | E12: A mission is assigned to current rescuer; request is in Assigned stage | F12: Passed | H12: TrungDN | I12: Passed | K12: KhoaPA | L12: Passed | N12: TrungDN
A13: TC902 | B13: Start mission transitions to EnRoute screen | C13: 1) Open assigned mission detail with deposit confirmed 2) Tap "BẮT ĐẦU DI CHUYỂN" 3) Wait for navigation | D13: App starts mission and opens EnRoute screen with header text "ĐANG DI CHUYỂN" | E13: Deposit is confirmed and missionId is available | F13: Passed | H13: TrungDN | I13: Passed | K13: KhoaPA | L13: Passed | N13: TrungDN
A14: TC903 | B14: EnRoute screen shows navigation and call tools | C14: 1) From EnRoute screen, inspect top controls 2) Tap navigation icon (external map) 3) Tap call icon when customer phone exists | D14: External navigation can be launched; call action opens phone dialer; EnRoute screen remains stable | E14: Mission is in EnRoute; request has destination and customer phone number | F14: Passed | H14: TrungDN | I14: Passed | K14: KhoaPA | L14: Passed | N14: TrungDN
A15: TC904 | B15: Arrived action is gated by distance > 1 km | C15: 1) Start in EnRoute while still far from destination (> 1 km) 2) Observe distance hint panel and action area | D15: UI shows hint text similar to "Còn cách ... nút "Đã đến nơi" hiện trong vòng 1 km" and arrival action is not available for confirmation | E15: Mission is EnRoute and live location is available with distance > 1 km | F15: Passed | H15: TrungDN | I15: Passed | K15: KhoaPA | L15: Passed | N15: TrungDN
A16: TC905 | B16: Arrived action appears within 1 km | C16: 1) Move/simulate location to within 1 km of destination 2) Observe EnRoute action area | D16: Floating action "ĐÃ ĐẾN NƠI" appears and hint changes to "Bạn đã gần đến nơi! Bấm "ĐÃ ĐẾN NƠI" ở phía trên" | E16: Mission is EnRoute and distance can be updated | F16: Passed | H16: TrungDN | I16: Passed | K16: KhoaPA | L16: Passed | N16: TrungDN
A17: TC906 | B17: Choosing "Đã đến nơi" transitions mission to Arrived flow | C17: 1) Open dialog "Xác nhận đến nơi" 2) Tap "Đã đến nơi" 3) Wait for API update and screen transition 4) Reopen job list/detail to verify status labels | D17: System calls arrived update, navigates to tracking flow, and mission status reflects Arrived (labels such as "Đã đến nơi" in job status) | E17: Mission is EnRoute; arrived endpoint is reachable | F17: Passed | H17: TrungDN | I17: Passed | K17: KhoaPA | L17: Passed | N17: TrungDN

Sheet Rescuer Mission Execution & Evi
A2: Feature | B2: Rescuer Mission Execution & Evidence Upload | R2: Passed
A3: Test requirement | B3: Rescuer executes on-site mission, uploads evidence photos, confirms snake details and environment, then submits final mission result to customer | R3: Failed
A4: Number of TCs | B4: =COUNTA(A12:A991) -> 6 | R4: Pending
A5: Testing Round | B5: Passed | C5: Failed | D5: Pending | E5: N/A | R5: N/A
A6: Round 1 | B6: =COUNTIF($F10:$F989,B5) -> 6 | C6: =COUNTIF($F10:$F989,C5) -> 0 | D6: =COUNTIF($F10:$F989,D5) -> 0 | E6: =COUNTIF($F10:$F989,E5) -> 0
A7: Round 2 | B7: =COUNTIF($I10:$I989,B5) -> 6 | C7: =COUNTIF($I10:$I989,C5) -> 0 | D7: =COUNTIF($I10:$I989,D5) -> 0 | E7: =COUNTIF($I10:$I989,E5) -> 0
A8: Round 3 | B8: =COUNTIF($L10:$L989,B5) -> 6 | C8: =COUNTIF($L10:$L989,C5) -> 0 | D8: =COUNTIF($L10:$L989,D5) -> 0 | E8: =COUNTIF($L10:$L989,E5) -> 0
A10: Test Case ID | B10: Test Case Description | C10: Test Case Procedure | D10: Expected Results | E10: Pre-conditions | F10: Round 1 | G10: Test date | H10: Tester | I10: Round 2 | J10: Test date | K10: Tester | L10: Round 3 | M10: Test date | N10: Tester | O10: Note
A11: Rescuer EnRoute & Arrived Tracking
A12: TC1001 | B12: Open mission execution screen after Arrived | C12: 1) Login as Rescuer 2) Open "Hoạt Động" Tab 3) Open an assigned mission already at Arrived state 4) Enter mission execution screen | D12: Screen title shows "Đang Bắt Rắn" with processing badge "ĐANG XỬ LÝ" | E12: Mission status is Arrived and belongs to current rescuer | F12: Passed | H12: TrungDN | I12: Passed | K12: KhoaPA | L12: Passed | N12: TrungDN
A13: TC1002 | B13: Start mission transitions to EnRoute screen | C13: 1) Login as Rescuer 2) Open "Hoạt Động" Tab 3) Enter mission execution screen 4)On "Đang Bắt Rắn" screen, tap area "Chụp ảnh rắn sau khi bắt" 5) Capture one photo from camera 6) Wait for upload | D13: Photo thumbnail appears, upload state completes, and progress label updates to "Đã tải 1/1" (or equivalent done count) | E13: Camera permission granted and network available | F13: Passed | H13: TrungDN | I13: Passed | K13: KhoaPA | L13: Passed | N13: TrungDN
A14: TC1003 | B14: Upload failure shows retry behavior | C14: 1) Login as Rescuer 2) Open "Hoạt Động" Tab 3) Enter mission execution screen 4)On "Đang Bắt Rắn" screen, tap area "Chụp ảnh rắn sau khi bắt" 5) Capture one photo from camera 6) Wait for upload 7) Trigger a photo upload failure (unstable network / server error) 8) Tap "Thử lại" on failed photo | D14: Snackbar appears with "Tải ảnh thất bại. Nhấn ’Thử lại’ trên ảnh để upload lại.", then retry can set state back to uploaded | E14: At least one captured photo exists and upload fails | F14: Passed | H14: TrungDN | I14: Passed | K14: KhoaPA | L14: Passed | N14: TrungDN
A15: TC1004 | B15: Complete button remains locked without uploaded photo | C15: 1) Login as Rescuer 2) Open "Hoạt Động" Tab 3) Enter mission execution screen 4)On "Đang Bắt Rắn" screen | D15: Bottom button is disabled and text shows "CẦN ÍT NHẤT 1 ẢNH" | E15: Rescuer has not uploaded any successful evidence photo | F15: Passed | H15: TrungDN | I15: Passed | K15: KhoaPA | L15: Passed | N15: TrungDN
A16: TC1005 | B16: Navigate to result confirmation after having uploaded photo | C16: "1) Login as Rescuer 2) Open "Hoạt Động" Tab 3) Enter mission execution screen 4)On "Đang Bắt Rắn" screen, tap area "Chụp ảnh rắn sau khi bắt" 5) Capture one photo from camera 6) Wait for upload 7) Upload at least one evidence photo successfully 8) Tap bottom button "HOÀN THÀNH BẮT RẮN" | D16: App navigates to screen "Xác Nhận Hoàn Thành" | E16: Mission is EnRoute and distance can be updated | F16: Passed | H16: TrungDN | I16: Passed | K16: KhoaPA | L16: Passed | N16: TrungDN
A17: TC1006 | B17: Choosing "Đã đến nơi" transitions mission to Arrived flow | C17: 1) Open dialog "Xác nhận đến nơi" 2) Tap "Đã đến nơi" 3) Wait for API update and screen transition 4) Reopen job list/detail to verify status labels | D17: System calls arrived update, navigates to tracking flow, and mission status reflects Arrived (labels such as "Đã đến nơi" in job status) | E17: Mission is EnRoute; arrived endpoint is reachable | F17: Passed | H17: TrungDN | I17: Passed | K17: KhoaPA | L17: Passed | N17: TrungDN

Sheet View & Filter Expert Directory
A2: Feature | B2: View & Filter Expert Directory | R2: Passed
A3: Test requirement | B3: Load expert directory from API, apply specialty/sort/search filters, keep realtime online presence in sync via SignalR, and open expert detail with complete profile data. | R3: Failed
A4: Number of TCs | B4: =COUNTA(A12:A991) -> 5 | R4: Pending
A5: Testing Round | B5: Passed | C5: Failed | D5: Pending | E5: N/A | R5: N/A
A6: Round 1 | B6: =COUNTIF($F10:$F989,B5) -> 5 | C6: =COUNTIF($F10:$F989,C5) -> 0 | D6: =COUNTIF($F10:$F989,D5) -> 0 | E6: =COUNTIF($F10:$F989,E5) -> 0
A7: Round 2 | B7: =COUNTIF($I10:$I989,B5) -> 5 | C7: =COUNTIF($I10:$I989,C5) -> 0 | D7: =COUNTIF($I10:$I989,D5) -> 0 | E7: =COUNTIF($I10:$I989,E5) -> 0
A8: Round 3 | B8: =COUNTIF($L10:$L989,B5) -> 5 | C8: =COUNTIF($L10:$L989,C5) -> 0 | D8: =COUNTIF($L10:$L989,D5) -> 0 | E8: =COUNTIF($L10:$L989,E5) -> 0
A10: Test Case ID | B10: Test Case Description | C10: Test Case Procedure | D10: Expected Results | E10: Pre-conditions | F10: Round 1 | G10: Test date | H10: Tester | I10: Round 2 | J10: Test date | K10: Tester | L10: Round 3 | M10: Test date | N10: Tester | O10: Note
A11: View & Filter Expert Directory
A12: TC1801 | B12: Expert list loads successfully with API data | C12: 1. Sign in as Member. 2. Click "Tư vấn chuyên gia" on Member home screen. 3. Click "đặt lịch mới" to find "Chuyên Gia Rắn". 4. Wait for list loading to complete. | D12: The app calls expert directory API and displays expert cards with name, specialty, rating, fee, and online indicator; online status is updated by SignalR snapshot/delta events when available. | E12: Member account is authenticated; expert API and SignalR hub are reachable. | F12: Passed | H12: KhoaPA | I12: Passed | K12: TrungDN | L12: Passed | N12: KhoaPA
A13: TC1802 | B13: Specialty filter and sort option are applied correctly | C13: 1. On "Chuyên Gia Rắn" screen. 2. Open "Sắp xếp theo" and choose "Đánh giá cao nhất". | D13: The displayed list is filtered by selected specialty and ordered by selected sort rule; active filter chips are shown and removable. | E13: Expert list has at least 3 records with different ratings. | F13: Passed | H13: KhoaPA | I13: Passed | K13: TrungDN | L13: Passed | N13: KhoaPA
A14: TC1803 | B14: Keyword search returns matching experts | C14: 1. On "Chuyên Gia Rắn", click search icon. 2. Enter a keyword from expert name. | D14: The list shows only matching experts and updates stats text with result count for the entered query. | E14: Expert list data includes records matching the keyword. | F14: Passed | H14: KhoaPA | I14: Passed | K14: TrungDN | L14: Passed | N14: KhoaPA
A15: TC1804 | B15: Expert detail loads profile, reviews, and availability in one flow | C15: 1. From expert list, open one expert card. 2. Observe profile sections "Giới Thiệu", "Kinh Nghiệm", "Thống Kê", "Phí Tư Vấn", "Lịch Trống", and review area. | D15: Expert detail screen is populated with API data from profile/reviews/time-slots aggregation. | E15: Expert detail endpoints are available for the selected expert. | F15: Passed | H15: KhoaPA | I15: Passed | K15: TrungDN | L15: Passed | N15: KhoaPA
A16: TC1805 | B16: Continue from expert detail to service selection | C16: 1. On expert detail screen, click "Đặt Tư Vấn". | D16: The app navigates to service selection route for the same expert and shows both consultation options. | E16: Expert detail screen is loaded successfully. | F16: Passed | H16: KhoaPA | I16: Passed | K16: TrungDN | L16: Passed | N16: KhoaPA

Sheet Book Instant Consultation
A2: Feature | B2: Book Instant Consultation | R2: Passed
A3: Test requirement | B3: Allow instant consultation booking only when expert is online, collect problem description, create emergency request, process payment, and track acceptance status in realtime. | R3: Failed
A4: Number of TCs | B4: =COUNTA(A12:A991) -> 5 | R4: Pending
A5: Testing Round | B5: Passed | C5: Failed | D5: Pending | E5: N/A | R5: N/A
A6: Round 1 | B6: =COUNTIF($F10:$F989,B5) -> 5 | C6: =COUNTIF($F10:$F989,C5) -> 0 | D6: =COUNTIF($F10:$F989,D5) -> 0 | E6: =COUNTIF($F10:$F989,E5) -> 0
A7: Round 2 | B7: =COUNTIF($I10:$I989,B5) -> 5 | C7: =COUNTIF($I10:$I989,C5) -> 0 | D7: =COUNTIF($I10:$I989,D5) -> 0 | E7: =COUNTIF($I10:$I989,E5) -> 0
A8: Round 3 | B8: =COUNTIF($L10:$L989,B5) -> 5 | C8: =COUNTIF($L10:$L989,C5) -> 0 | D8: =COUNTIF($L10:$L989,D5) -> 0 | E8: =COUNTIF($L10:$L989,E5) -> 0
A10: Test Case ID | B10: Test Case Description | C10: Test Case Procedure | D10: Expected Results | E10: Pre-conditions | F10: Round 1 | G10: Test date | H10: Tester | I10: Round 2 | J10: Test date | K10: Tester | L10: Round 3 | M10: Test date | N10: Tester | O10: Note
A11: Book Instant Consultation
A12: TC1901 | B12: Instant consultation option is disabled when expert is offline | C12: 1. Open service selection for an expert currently shown as offline. 2. Observe instant card "Tư Vấn Ngay" and the button "Chọn Tư Vấn Ngay". | D12: Instant action is disabled; user cannot proceed until expert is online. | E12: Selected expert is offline according to realtime presence. | F12: Passed | H12: KhoaPA | I12: Passed | K12: TrungDN | L12: Passed | N12: KhoaPA
A13: TC1902 | B13: Instant flow moves to documents and requires problem description | C13: 1. Open service selection for an online expert and click "Chọn Tư Vấn Ngay". 2. On "Tài Liệu Tư Vấn", leave "Mô Tả Vấn Đề" empty and click continue button. | D13: App stays on documents screen and shows validation message "Vui lòng mô tả vấn đề của bạn". | E13: Selected expert is online. | F13: Passed | H13: KhoaPA | I13: Passed | K13: TrungDN | L13: Passed | N13: KhoaPA
A14: TC1903 | B14: Instant payment with SnakeAidPay creates request and opens waiting modal | C14: 1. Fill valid problem description on instant documents screen. 2. Continue to "Xác Nhận & Thanh Toán". 3. Select "SnakeAid Pay", accept "Chính Sách Thanh Toán", and click "Xác Nhận & Thanh Toán". | D14: App creates emergency request and shows emergency waiting modal with message "Đã thanh toán. Đang chờ chuyên gia phản hồi...". | E14: Member wallet balance is sufficient; instant payment API is available. | F14: Passed | H14: KhoaPA | I14: Passed | K14: TrungDN | L14: Passed | N14: KhoaPA
A15: TC1904 | B15: Instant payment with PayOS launches external checkout and supports callback confirmation | C15: 1. From instant payment screen, select "PayOS" and confirm payment. 2. Complete payment in PayOS and return to app via callback/deep link. | D15: App opens PayOS checkout URL, verifies callback, and enters emergency waiting modal; fallback confirmation API is used if needed before finalizing. | E15: PayOS integration and deep-link callback are configured. | F15: Passed | H15: KhoaPA | I15: Passed | K15: TrungDN | L15: Passed | N15: DuongNM
A16: TC1905 | B16: Instant waiting handles realtime acceptance and routes to video waiting room | C16: 1. After instant payment, keep emergency waiting modal open. 2. From expert side, accept the same request. | D16: Member waiting modal status changes to accepted and app navigates to member video waiting room route with the accepted consultationId. | E16: Expert account can receive and accept the same emergency request. | F16: Passed | H16: KhoaPA | I16: Passed | K16: TrungDN | L16: Passed | N16: KhoaPA

Sheet Book Scheduled Consultation
A2: Feature | B2: Book Scheduled Consultation | R2: Passed
A3: Test requirement | B3: Show available time slots from API, enforce valid slot/problem input, create booking with real timeSlotId, and continue to payment with booking identifiers. | R3: Failed
A4: Number of TCs | B4: =COUNTA(A12:A991) -> 5 | R4: Pending
A5: Testing Round | B5: Passed | C5: Failed | D5: Pending | E5: N/A | R5: N/A
A6: Round 1 | B6: =COUNTIF($F10:$F989,B5) -> 5 | C6: =COUNTIF($F10:$F989,C5) -> 0 | D6: =COUNTIF($F10:$F989,D5) -> 0 | E6: =COUNTIF($F10:$F989,E5) -> 0
A7: Round 2 | B7: =COUNTIF($I10:$I989,B5) -> 5 | C7: =COUNTIF($I10:$I989,C5) -> 0 | D7: =COUNTIF($I10:$I989,D5) -> 0 | E7: =COUNTIF($I10:$I989,E5) -> 0
A8: Round 3 | B8: =COUNTIF($L10:$L989,B5) -> 5 | C8: =COUNTIF($L10:$L989,C5) -> 0 | D8: =COUNTIF($L10:$L989,D5) -> 0 | E8: =COUNTIF($L10:$L989,E5) -> 0
A10: Test Case ID | B10: Test Case Description | C10: Test Case Procedure | D10: Expected Results | E10: Pre-conditions | F10: Round 1 | G10: Test date | H10: Tester | I10: Round 2 | J10: Test date | K10: Tester | L10: Round 3 | M10: Test date | N10: Tester | O10: Note
A11: Book Scheduled Consultation
A12: TC2001 | B12: Scheduled option is unavailable when expert has no availability slot | C12: 1. Open service selection for an expert with no available slots. 2. Observe "Đặt Lịch Tư Vấn" card and click "Chọn Đặt Lịch". | D12: App shows "Chuyên gia chưa có lịch trống" and disables booking action; user cannot proceed to time selection. | E12: Selected expert has empty availability slot from API. | F12: Passed | H12: KhoaPA | I12: Passed | K12: TrungDN | L12: Passed | N12: KhoaPA
A13: TC2002 | B13: Time selection shows only valid future slots and requires selection | C13: 1. Open "Chọn Thời Gian" for an expert with availability. 2. Select no date/time. | D13: App blocks progression and shows "Vui lòng chọn ngày và giờ tư vấn"; date/slot grid only contains non-expired slots according to current time rules. | E13: Expert time-slot API returns at least one available day. | F13: Passed | H13: KhoaPA | I13: Passed | K13: TrungDN | L13: Passed | N13: KhoaPA
A14: TC2003 | B14: Scheduled documents call create-booking API with real timeSlotId | C14: 1. Select date and slot, then navigate to "Tài Liệu Tư Vấn". 2. Enter valid "Mô Tả Vấn Đề" and click "Xác Nhận Đặt Lịch". | D14: App calls scheduled booking API and receives booking with bookingId/consultationId; then navigates to payment confirmation with those identifiers in flow data. | E14: Selected slot is still available; booking API is reachable. | F14: Passed | H14: KhoaPA | I14: Passed | K14: TrungDN | L14: Passed | N14: KhoaPA
A15: TC2004 | B15: Concurrent slot conflict returns friendly message | C15: 1. Reach scheduled documents screen with a slot that has just been taken by another user. 2. Click "Xác Nhận Đặt Lịch". | D15: App stays on screen and shows conflict message "Khung giờ này vừa được đặt bởi người khác. Vui lòng chọn giờ khác.". | E15: Slot conflict can be simulated (backend returns HTTP 409). | F15: Passed | H15: KhoaPA | I15: Passed | K15: TrungDN | L15: Passed | N15: KhoaPA
A16: TC2005 | B16: Scheduled payment success sends user back to consultation home with highlight | C16: 1. Complete scheduled payment (Wallet or PayOS callback success). 2. Observe navigation result. | D16: App invalidates bookings data and routes to consultation home, passing new consultation/booking ID so the corresponding card is highlighted. | E16: Scheduled booking exists in pending-payment state. | F16: Passed | H16: KhoaPA | I16: Passed | K16: TrungDN | L16: Passed | N16: DuongNM

Sheet Process Consultation Escrow Pay
A2: Feature | B2: Process Consultation Escrow Payment | R2: Passed
A3: Test requirement | B3: Enforce payment policy acknowledgment, support PayOS and wallet flows, handle insufficient wallet/top-up and callback verification, and keep consultation payment status consistent. | R3: Failed
A4: Number of TCs | B4: =COUNTA(A12:A992) -> 6 | R4: Pending
A5: Testing Round | B5: Passed | C5: Failed | D5: Pending | E5: N/A | R5: N/A
A6: Round 1 | B6: =COUNTIF($F10:$F990,B5) -> 6 | C6: =COUNTIF($F10:$F990,C5) -> 0 | D6: =COUNTIF($F10:$F990,D5) -> 0 | E6: =COUNTIF($F10:$F990,E5) -> 0
A7: Round 2 | B7: =COUNTIF($I10:$I990,B5) -> 6 | C7: =COUNTIF($I10:$I990,C5) -> 0 | D7: =COUNTIF($I10:$I990,D5) -> 0 | E7: =COUNTIF($I10:$I990,E5) -> 0
A8: Round 3 | B8: =COUNTIF($L10:$L990,B5) -> 6 | C8: =COUNTIF($L10:$L990,C5) -> 0 | D8: =COUNTIF($L10:$L990,D5) -> 0 | E8: =COUNTIF($L10:$L990,E5) -> 0
A10: Test Case ID | B10: Test Case Description | C10: Test Case Procedure | D10: Expected Results | E10: Pre-conditions | F10: Round 1 | G10: Test date | H10: Tester | I10: Round 2 | J10: Test date | K10: Tester | L10: Round 3 | M10: Test date | N10: Tester | O10: Note
A11: Process Consultation Escrow Payment
A12: TC2101 | B12: Payment cannot proceed before policy acknowledgment | C12: 1. Open "Xác Nhận & Thanh Toán". 2. Do not tick "Tôi đã đọc và hiểu Chính Sách Thanh Toán bên trên.". 3. Click "Xác Nhận & Thanh Toán". | D12: App does not submit payment and shows warning requiring policy acknowledgment. | E12: Payment confirmation screen is loaded with valid booking or instant flow. | F12: Passed | H12: KhoaPA | I12: Passed | K12: TrungDN | L12: Passed | N12: KhoaPA
A13: TC2102 | B13: Security and policy content reflect escrow behavior | C13: 1. Open payment screen and expand "Chính Sách Thanh Toán". 2. Review security box and policy bullets. | D13: UI explains escrow handling and non-self-cancel rule after successful payment; instant flow policy includes refund rule when expert does not accept. | E13: Payment confirmation screen is reachable. | F13: Passed | H13: KhoaPA | I13: Passed | K13: TrungDN | L13: Passed | N13: KhoaPA
A14: TC2103 | B14: Wallet method fails gracefully on insufficient balance and supports top-up | C14: 1. Select "SnakeAid Pay" with wallet balance lower than consultation price. 2. Open wallet confirmation dialog and click "Nạp ví ngay". | D14: Confirm action remains disabled until balance is enough; app opens PayOS top-up, then refreshes wallet and allows payment after successful top-up callback/verification. | E14: Wallet exists with insufficient balance; top-up API and callback are available. | F14: Passed | H14: KhoaPA | I14: Passed | K14: TrungDN | L14: Passed | N14: KhoaPA
A15: TC2104 | B15: PayOS flow handles callback success and fallback confirm | C15: 1. Select "PayOS" and confirm consultation payment. 2. Complete checkout and return to app. | D15: App verifies callback event; if pending, fallback confirm API is triggered; on confirmed status, app routes to waiting/home flow and clears pending PayOS context. | E15: PayOS checkout can be completed; deep-link callback is configured. | F15: Passed | H15: KhoaPA | I15: Passed | K15: DuongNM | L15: Passed | N15: DuongNM
